<?xml version="1.0"?>
<!--
Sample Humanoid Robot URDF
Used in Module 2 Labs for Gazebo simulation
Includes: torso, head, arms, legs with basic sensors
For use: ros2 launch my_robot gazebo.launch.xml
-->
<robot name="humanoid">
  <!-- ========== BASE LINK (TORSO) ========== -->
  <link name="base_link">
    <visual>
      <geometry>
        <box size="0.2 0.2 0.5"/>
      </geometry>
      <material name="blue">
        <color rgba="0 0 1 1"/>
      </material>
    </visual>
    <collision>
      <geometry>
        <box size="0.2 0.2 0.5"/>
      </geometry>
    </collision>
    <inertial>
      <mass value="10"/>
      <inertia ixx="0.1" iyy="0.1" izz="0.1" ixy="0" ixz="0" iyz="0"/>
    </inertial>
  </link>

  <!-- ========== HEAD ========== -->
  <link name="head">
    <visual>
      <geometry>
        <sphere radius="0.08"/>
      </geometry>
      <material name="yellow">
        <color rgba="1 1 0 1"/>
      </material>
    </visual>
    <collision>
      <geometry>
        <sphere radius="0.08"/>
      </geometry>
    </collision>
    <inertial>
      <mass value="2"/>
      <inertia ixx="0.01" iyy="0.01" izz="0.01" ixy="0" ixz="0" iyz="0"/>
    </inertial>
  </link>

  <joint name="neck_joint" type="revolute">
    <parent link="base_link"/>
    <child link="head"/>
    <origin xyz="0 0 0.3" rpy="0 0 0"/>
    <axis xyz="0 0 1"/>
    <limit lower="-1.57" upper="1.57" effort="10" velocity="1.0"/>
  </joint>

  <!-- ========== CAMERA SENSOR ========== -->
  <link name="camera_link">
    <visual>
      <geometry>
        <box size="0.05 0.05 0.05"/>
      </geometry>
      <material name="black">
        <color rgba="0 0 0 1"/>
      </material>
    </visual>
    <collision>
      <geometry>
        <box size="0.05 0.05 0.05"/>
      </geometry>
    </collision>
    <inertial>
      <mass value="0.1"/>
      <inertia ixx="0.001" iyy="0.001" izz="0.001" ixy="0" ixz="0" iyz="0"/>
    </inertial>
  </link>

  <joint name="camera_joint" type="fixed">
    <parent link="head"/>
    <child link="camera_link"/>
    <origin xyz="0 0 0.08" rpy="0 0 0"/>
  </joint>

  <!-- ========== LIDAR SENSOR ========== -->
  <link name="lidar_link">
    <visual>
      <geometry>
        <cylinder radius="0.04" length="0.03"/>
      </geometry>
      <material name="purple">
        <color rgba="1 0 1 1"/>
      </material>
    </visual>
    <collision>
      <geometry>
        <cylinder radius="0.04" length="0.03"/>
      </geometry>
    </collision>
    <inertial>
      <mass value="0.2"/>
      <inertia ixx="0.001" iyy="0.001" izz="0.001" ixy="0" ixz="0" iyz="0"/>
    </inertial>
  </link>

  <joint name="lidar_joint" type="fixed">
    <parent link="head"/>
    <child link="lidar_link"/>
    <origin xyz="0 0 0.12" rpy="0 0 0"/>
  </joint>

  <!-- ========== LEFT ARM ========== -->
  <link name="left_arm">
    <visual>
      <geometry>
        <cylinder radius="0.05" length="0.4"/>
      </geometry>
      <material name="red">
        <color rgba="1 0 0 1"/>
      </material>
    </visual>
    <collision>
      <geometry>
        <cylinder radius="0.05" length="0.4"/>
      </geometry>
    </collision>
    <inertial>
      <mass value="2"/>
      <inertia ixx="0.01" iyy="0.01" izz="0.01" ixy="0" ixz="0" iyz="0"/>
    </inertial>
  </link>

  <joint name="left_arm_joint" type="revolute">
    <parent link="base_link"/>
    <child link="left_arm"/>
    <origin xyz="0.15 0 0.1" rpy="0 1.57 0"/>
    <axis xyz="1 0 0"/>
    <limit lower="-3.14" upper="3.14" effort="20" velocity="1.57"/>
  </joint>

  <!-- ========== RIGHT ARM ========== -->
  <link name="right_arm">
    <visual>
      <geometry>
        <cylinder radius="0.05" length="0.4"/>
      </geometry>
      <material name="green">
        <color rgba="0 1 0 1"/>
      </material>
    </visual>
    <collision>
      <geometry>
        <cylinder radius="0.05" length="0.4"/>
      </geometry>
    </collision>
    <inertial>
      <mass value="2"/>
      <inertia ixx="0.01" iyy="0.01" izz="0.01" ixy="0" ixz="0" iyz="0"/>
    </inertial>
  </link>

  <joint name="right_arm_joint" type="revolute">
    <parent link="base_link"/>
    <child link="right_arm"/>
    <origin xyz="-0.15 0 0.1" rpy="0 1.57 0"/>
    <axis xyz="1 0 0"/>
    <limit lower="-3.14" upper="3.14" effort="20" velocity="1.57"/>
  </joint>

  <!-- ========== LEFT LEG ========== -->
  <link name="left_leg">
    <visual>
      <geometry>
        <cylinder radius="0.06" length="0.5"/>
      </geometry>
      <material name="cyan">
        <color rgba="0 1 1 1"/>
      </material>
    </visual>
    <collision>
      <geometry>
        <cylinder radius="0.06" length="0.5"/>
      </geometry>
    </collision>
    <inertial>
      <mass value="3"/>
      <inertia ixx="0.02" iyy="0.02" izz="0.02" ixy="0" ixz="0" iyz="0"/>
    </inertial>
  </link>

  <joint name="left_leg_joint" type="revolute">
    <parent link="base_link"/>
    <child link="left_leg"/>
    <origin xyz="0.05 0 -0.3" rpy="0 0 0"/>
    <axis xyz="1 0 0"/>
    <limit lower="-1.57" upper="1.57" effort="50" velocity="1.57"/>
  </joint>

  <!-- ========== RIGHT LEG ========== -->
  <link name="right_leg">
    <visual>
      <geometry>
        <cylinder radius="0.06" length="0.5"/>
      </geometry>
      <material name="magenta">
        <color rgba="1 0 1 1"/>
      </material>
    </visual>
    <collision>
      <geometry>
        <cylinder radius="0.06" length="0.5"/>
      </geometry>
    </collision>
    <inertial>
      <mass value="3"/>
      <inertia ixx="0.02" iyy="0.02" izz="0.02" ixy="0" ixz="0" iyz="0"/>
    </inertial>
  </link>

  <joint name="right_leg_joint" type="revolute">
    <parent link="base_link"/>
    <child link="right_leg"/>
    <origin xyz="-0.05 0 -0.3" rpy="0 0 0"/>
    <axis xyz="1 0 0"/>
    <limit lower="-1.57" upper="1.57" effort="50" velocity="1.57"/>
  </joint>

  <!-- ========== GAZEBO PLUGINS ========== -->

  <!-- Camera sensor plugin -->
  <gazebo reference="camera_link">
    <sensor type="camera" name="camera">
      <always_on>true</always_on>
      <update_rate>30</update_rate>
      <visualize>true</visualize>
      <camera>
        <horizontal_fov>1.047</horizontal_fov>
        <image>
          <width>640</width>
          <height>480</height>
          <format>R8G8B8</format>
        </image>
        <clip>
          <near>0.05</near>
          <far>100</far>
        </clip>
      </camera>
      <plugin name="camera_plugin" filename="libgazebo_ros_camera.so">
        <ros>
          <remapping>~/image_raw:=/camera/image_raw</remapping>
          <remapping>~/camera_info:=/camera/camera_info</remapping>
        </ros>
        <camera_name>camera</camera_name>
        <frame_name>camera_link</frame_name>
      </plugin>
    </sensor>
  </gazebo>

  <!-- LiDAR sensor plugin -->
  <gazebo reference="lidar_link">
    <sensor type="gpu_lidar" name="lidar">
      <always_on>true</always_on>
      <update_rate>10</update_rate>
      <lidar>
        <scan>
          <horizontal>
            <samples>360</samples>
            <resolution>1</resolution>
            <min_angle>0</min_angle>
            <max_angle>6.283</max_angle>
          </horizontal>
        </scan>
        <range>
          <min>0.08</min>
          <max>100</max>
          <resolution>0.01</resolution>
        </range>
      </lidar>
      <plugin name="gpu_lidar" filename="libgazebo_ros_gpu_lidar.so">
        <ros>
          <remapping>~/scan:=/scan</remapping>
        </ros>
        <frame_name>lidar_link</frame_name>
      </plugin>
    </sensor>
  </gazebo>

  <!-- Joint state broadcaster -->
  <gazebo>
    <plugin name="gazebo_ros_joint_state_broadcaster"
            filename="libgazebo_ros_joint_state_broadcaster.so">
      <ros>
        <remapping>~/out:=joint_states</remapping>
      </ros>
      <update_rate>100</update_rate>
    </plugin>
  </gazebo>

  <!-- Joint controllers -->
  <gazebo>
    <plugin name="gazebo_ros_joint_trajectory_controller"
            filename="libgazebo_ros_joint_trajectory_controller.so">
      <ros>
        <remapping>~/joint_trajectory:=/left_arm_controller/joint_trajectory</remapping>
      </ros>
      <joint_name>left_arm_joint</joint_name>
    </plugin>
  </gazebo>

  <gazebo>
    <plugin name="gazebo_ros_joint_trajectory_controller"
            filename="libgazebo_ros_joint_trajectory_controller.so">
      <ros>
        <remapping>~/joint_trajectory:=/right_arm_controller/joint_trajectory</remapping>
      </ros>
      <joint_name>right_arm_joint</joint_name>
    </plugin>
  </gazebo>

  <gazebo>
    <plugin name="gazebo_ros_joint_trajectory_controller"
            filename="libgazebo_ros_joint_trajectory_controller.so">
      <ros>
        <remapping>~/joint_trajectory:=/left_leg_controller/joint_trajectory</remapping>
      </ros>
      <joint_name>left_leg_joint</joint_name>
    </plugin>
  </gazebo>

  <gazebo>
    <plugin name="gazebo_ros_joint_trajectory_controller"
            filename="libgazebo_ros_joint_trajectory_controller.so">
      <ros>
        <remapping>~/joint_trajectory:=/right_leg_controller/joint_trajectory</remapping>
      </ros>
      <joint_name>right_leg_joint</joint_name>
    </plugin>
  </gazebo>

</robot>
